Traceback (most recent call last):
  File "C:\Users\bjtja\anaconda3\envs\test_update_py\lib\site-packages\jupyter_cache\executors\utils.py", line 51, in single_nb_execution
    executenb(
  File "C:\Users\bjtja\anaconda3\envs\test_update_py\lib\site-packages\nbclient\client.py", line 1117, in execute
    return NotebookClient(nb=nb, resources=resources, km=km, **kwargs).execute()
  File "C:\Users\bjtja\anaconda3\envs\test_update_py\lib\site-packages\nbclient\util.py", line 78, in wrapped
    return just_run(coro(*args, **kwargs))
  File "C:\Users\bjtja\anaconda3\envs\test_update_py\lib\site-packages\nbclient\util.py", line 57, in just_run
    return loop.run_until_complete(coro)
  File "C:\Users\bjtja\anaconda3\envs\test_update_py\lib\asyncio\base_events.py", line 642, in run_until_complete
    return future.result()
  File "C:\Users\bjtja\anaconda3\envs\test_update_py\lib\site-packages\nbclient\client.py", line 558, in async_execute
    await self.async_execute_cell(
  File "C:\Users\bjtja\anaconda3\envs\test_update_py\lib\site-packages\nbclient\client.py", line 862, in async_execute_cell
    self._check_raise_for_error(cell, exec_reply)
  File "C:\Users\bjtja\anaconda3\envs\test_update_py\lib\site-packages\nbclient\client.py", line 765, in _check_raise_for_error
    raise CellExecutionError.from_cell_and_msg(cell, exec_reply_content)
nbclient.exceptions.CellExecutionError: An error occurred while executing the following cell:
------------------
# Set up report tables
# HIDDEN

import ReportTables
# from importlib import reload
# reload(ReportTables)

ReportTables.run()
------------------

[1;31m---------------------------------------------------------------------------[0m
[1;31mAttributeError[0m                            Traceback (most recent call last)
[1;32m~\AppData\Local\Temp/ipykernel_25264/23522014.py[0m in [0;36m<module>[1;34m[0m
[0;32m      6[0m [1;31m# reload(ReportTables)[0m[1;33m[0m[1;33m[0m[1;33m[0m[0m
[0;32m      7[0m [1;33m[0m[0m
[1;32m----> 8[1;33m [0mReportTables[0m[1;33m.[0m[0mrun[0m[1;33m([0m[1;33m)[0m[1;33m[0m[1;33m[0m[0m
[0m
[1;32m~\OneDrive\2021\DnD2021\caterpillar-stat-generation\src\ReportTables.py[0m in [0;36mrun[1;34m()[0m
[0;32m     47[0m   [0maxes[0m[1;33m.[0m[0mgrid[0m[1;33m([0m[1;32mTrue[0m[1;33m)[0m[1;33m[0m[1;33m[0m[0m
[0;32m     48[0m   [0mglue[0m[1;33m([0m[1;34m"stats_distribution_fig"[0m[1;33m,[0m [0mfig[0m[1;33m,[0m [0mdisplay[0m[1;33m=[0m[1;32mFalse[0m[1;33m)[0m[1;33m[0m[1;33m[0m[0m
[1;32m---> 49[1;33m   [0mfig[0m[1;33m.[0m[0mclose[0m[1;33m([0m[1;33m)[0m[1;33m[0m[1;33m[0m[0m
[0m[0;32m     50[0m [1;33m[0m[0m
[0;32m     51[0m   [1;31m# Create summary stats[0m[1;33m[0m[1;33m[0m[1;33m[0m[0m

[1;31mAttributeError[0m: 'Figure' object has no attribute 'close'
AttributeError: 'Figure' object has no attribute 'close'

